<?xml version="1.0"?>
<sdf version="1.5">
	<model name="SixAxis">
		<plugin name="attachModule" filename="{baseDir}libattach_plugin.so">
			<parentModel>{parentModel}</parentModel>
			<parentLink>{parentLink}</parentLink>
			<childLink>{childLink}</childLink>
		</plugin>
		<plugin name="motorManager" filename="{baseDir}libmotor_manager_plugin.so">
			<motors>upperArm1ToBase upperArm2ToBase upperArm3ToBase upperArm4ToBase upperArm5ToBase upperArm6ToBase</motors>
		</plugin>
		<static>false</static>
		<!--==================== Links ====================-->
		<link name="base">
			<pose>0 0 0 0 0 0</pose>
			<gravity>false</gravity>
			
			<inertial>
				<mass>20.000</mass>
			</inertial>
			<visual name="visual">
				<geometry>
					<mesh>
						<uri>file://{baseDir}base.dae</uri>
					</mesh>
				</geometry>
			</visual>
		</link>
		<!-- Upper arms --> 
		<link name="upperArm1"> 
			<pose>0.1557 -0.1397 -0.0345 0 0 2.0943951</pose>
			<gravity>true</gravity>
			
			<inertial>
				<mass>0.200</mass>
				<pose>0 -0.050 0 0 0 0</pose>
			</inertial>
			<visual name="visual">
				<geometry>
					<mesh>
						<uri>file://{baseDir}upperArm.dae</uri>
					</mesh>
				</geometry>
			</visual>
		</link>
		<link name="upperArm2"> 
			<pose>0.1676 -0.1603 -0.0345 0 3.14159265 2.0943951</pose>
			<gravity>true</gravity>
			
			<inertial>
				<mass>0.200</mass>
				<pose>0 -0.050 0 0 0 0</pose>
			</inertial>
			<visual name="visual">
				<geometry>
					<mesh>
						<uri>file://{baseDir}upperArm.dae</uri>
					</mesh>
				</geometry>
			</visual>
		</link>
		<link name="upperArm3"> 
			<pose>0.0869 -0.3000 -0.0345 0 0 0</pose>
			<gravity>true</gravity>
			
			<inertial>
				<mass>0.200</mass>
				<pose>0 -0.050 0 0 0 0</pose>
			</inertial>
			<visual name="visual">
				<geometry>
					<mesh>
						<uri>file://{baseDir}upperArm.dae</uri>
					</mesh>
				</geometry>
			</visual>
		</link>
		<link name="upperArm4"> 
			<pose>0.0631 -0.3000 -0.0345 0 3.14159265 0</pose>
			<gravity>true</gravity>
			
			<inertial>
				<mass>0.200</mass>
				<pose>0 -0.050 0 0 0 0</pose>
			</inertial>
			<visual name="visual">
				<geometry>
					<mesh>
						<uri>file://{baseDir}upperArm.dae</uri>
					</mesh>
				</geometry>
			</visual>
		</link>
		<link name="upperArm5"> 
			<pose>-0.0176 -0.1603 -0.0345 0 0 -2.0943951</pose>
			<gravity>true</gravity>
			
			<inertial>
				<mass>0.200</mass>
				<pose>0 -0.050 0 0 0 0</pose>
			</inertial>
			<visual name="visual">
				<geometry>
					<mesh>
						<uri>file://{baseDir}upperArm.dae</uri>
					</mesh>
				</geometry>
			</visual>
		</link>
		<link name="upperArm6"> 
			<pose>-0.0057 -0.1397 -0.0345 0 3.14159265 -2.0943951</pose>
			<gravity>true</gravity>
			
			<inertial>
				<mass>0.200</mass>
				<pose>0 -0.050 0 0 0 0</pose>
			</inertial>
			<visual name="visual">
				<geometry>
					<mesh>
						<uri>file://{baseDir}upperArm.dae</uri>
					</mesh>
				</geometry>
			</visual>
		</link>
		<!-- Lower arms --> 
		<link name="lowerArm1"> 
			<pose>0.2324 -0.07255 -0.0345 0.5527151 0 2.0943951</pose>
			<gravity>true</gravity>
			
			<inertial>
				<mass>0.040</mass>
				<pose>0 0 -0.150 0 0 0</pose>
			</inertial>
			<visual name="visual">
				<geometry>
					<mesh>
						<uri>file://{baseDir}lowerArm.dae</uri>
					</mesh>
				</geometry>
			</visual>
		</link>
		<link name="lowerArm2"> 
			<pose>0.2641 -0.1275 -0.0345 0.5527151 0 2.0943951</pose>
			<gravity>true</gravity>
			
			<inertial>
				<mass>0.040</mass>
				<pose>0 0 -0.150 0 0 0</pose>
			</inertial>
			<visual name="visual">
				<geometry>
					<mesh>
						<uri>file://{baseDir}lowerArm.dae</uri>
					</mesh>
				</geometry>
			</visual>
		</link>
		<link name="lowerArm3"> 
			<pose>0.1067 -0.4000 -0.0345 0.5527151 0 0</pose>
			<gravity>true</gravity>
			
			<inertial>
				<mass>0.040</mass>
				<pose>0 0 -0.150 0 0 0</pose>
			</inertial>
			<visual name="visual">
				<geometry>
					<mesh>
						<uri>file://{baseDir}lowerArm.dae</uri>
					</mesh>
				</geometry>
			</visual>
		</link>
		<link name="lowerArm4"> 
			<pose>0.0433 -0.4000 -0.0345 0.5527151 0 0</pose>
			<gravity>true</gravity>
			
			<inertial>
				<mass>0.040</mass>
				<pose>0 0 -0.150 0 0 0</pose>
			</inertial>
			<visual name="visual">
				<geometry>
					<mesh>
						<uri>file://{baseDir}lowerArm.dae</uri>
					</mesh>
				</geometry>
			</visual>
		</link>
		<link name="lowerArm5"> 
			<pose>-0.1141 -0.1275 -0.0345 0.5527151 0 -2.0943951</pose>
			<gravity>true</gravity>
			
			<inertial>
				<mass>0.040</mass>
				<pose>0 0 -0.150 0 0 0</pose>
			</inertial>
			<visual name="visual">
				<geometry>
					<mesh>
						<uri>file://{baseDir}lowerArm.dae</uri>
					</mesh>
				</geometry>
			</visual>
		</link>
		<link name="lowerArm6"> 
			<pose>-0.0824 -0.07255 -0.0345 0.5527151 0 -2.0943951</pose>
			<gravity>true</gravity>
			
			<inertial>
				<mass>0.040</mass>
				<pose>0 0 -0.150 0 0 0</pose>
			</inertial>
			<visual name="visual">
				<geometry>
					<mesh>
						<uri>file://{baseDir}lowerArm.dae</uri>
					</mesh>
				</geometry>
			</visual>
		</link>
		<!-- Effector --> 
		<link name="effector"> 
			<pose>0.075 -0.200 -0.2993 0 0 0</pose>
			<gravity>true</gravity>
			
			<inertial>
				<mass>0.100</mass>
			</inertial>
			<visual name="visual">
				<geometry>
					<mesh>
						<uri>file://{baseDir}effector.dae</uri>
					</mesh>
				</geometry>
			</visual>
		</link>
		
		<!--==================== Joints ====================-->
		<joint type="prismatic" name="baseToParent">
			<pose>0 0 0 0 0 0</pose>
			<parent>world</parent>
			<child>base</child>
			<axis>
				<xyz>1 0 0</xyz>
				<limit>
					<upper>0.0</upper>
					<lower>0.0</lower>
				</limit>
			</axis>
		</joint>
		<!-- Upper arms --> 
		<joint type="revolute" name="upperArm1ToBase"> 
			<parent>base</parent>
			<child>upperArm1</child>
			<axis>
				<xyz>1 0 0</xyz>
				<dynamics>
					<friction>0.05</friction>
					<damping>0.25</damping>
				</dynamics>
				<limit>
					<upper>3.14159265</upper>
					<lower>-3.14159265</lower>
				</limit>
			</axis>
		</joint>
		<joint type="revolute" name="upperArm2ToBase"> 
			<parent>base</parent>
			<child>upperArm2</child>
			<axis>
				<xyz>1 0 0</xyz>
				<dynamics>
					<friction>0.05</friction>
					<damping>0.25</damping>
				</dynamics>
				<limit>
					<upper>3.14159265</upper>
					<lower>-3.14159265</lower>
				</limit>
			</axis>
		</joint>
		<joint type="revolute" name="upperArm3ToBase"> 
			<parent>base</parent>
			<child>upperArm3</child>
			<axis>
				<xyz>1 0 0</xyz>
				<dynamics>
					<friction>0.05</friction>
					<damping>0.25</damping>
				</dynamics>
				<limit>
					<upper>3.14159265</upper>
					<lower>-3.14159265</lower>
				</limit>
			</axis>
		</joint>
		<joint type="revolute" name="upperArm4ToBase"> 
			<parent>base</parent>
			<child>upperArm4</child>
			<axis>
				<xyz>1 0 0</xyz>
				<dynamics>
					<friction>0.05</friction>
					<damping>0.25</damping>
				</dynamics>
				<limit>
					<upper>3.14159265</upper>
					<lower>-3.14159265</lower>
				</limit>
			</axis>
		</joint>
		<joint type="revolute" name="upperArm5ToBase"> 
			<parent>base</parent>
			<child>upperArm5</child>
			<axis>
				<xyz>1 0 0</xyz>
				<dynamics>
					<friction>0.05</friction>
					<damping>0.25</damping>
				</dynamics>
				<limit>
					<upper>3.14159265</upper>
					<lower>-3.14159265</lower>
				</limit>
			</axis>
		</joint>
		<joint type="revolute" name="upperArm6ToBase"> 
			<parent>base</parent>
			<child>upperArm6</child>
			<axis>
				<xyz>1 0 0</xyz>
				<dynamics>
					<friction>0.05</friction>
					<damping>0.25</damping>
				</dynamics>
				<limit>
					<upper>3.14159265</upper>
					<lower>-3.14159265</lower>
				</limit>
			</axis>
		</joint>
		<!-- Lower arms --> 
		<joint type="universal" name="lowerArm1ToUpperArm1"> 
			<parent>upperArm1</parent>
			<child>lowerArm1</child>
			<axis>
				<xyz>0 1 0</xyz>
				<dynamics>
					<friction>0.01</friction>
					<damping>0.1</damping>
				</dynamics>
			</axis>
			<axis2>
				<xyz>1 0 0</xyz>
				<dynamics>
					<friction>0.01</friction>
					<damping>0.1</damping>
				</dynamics>
			</axis2>
		</joint>
		<joint type="universal" name="lowerArm2ToUpperArm2"> 
			<parent>upperArm2</parent>
			<child>lowerArm2</child>
			<axis>
				<xyz>0 1 0</xyz>
				<dynamics>
					<friction>0.01</friction>
					<damping>0.1</damping>
				</dynamics>
			</axis>
			<axis2>
				<xyz>1 0 0</xyz>
				<dynamics>
					<friction>0.01</friction>
					<damping>0.1</damping>
				</dynamics>
			</axis2>
		</joint>
		<joint type="universal" name="lowerArm3ToUpperArm3"> 
			<parent>upperArm3</parent>
			<child>lowerArm3</child>
			<axis>
				<xyz>0 1 0</xyz>
				<dynamics>
					<friction>0.01</friction>
					<damping>0.1</damping>
				</dynamics>
			</axis>
			<axis2>
				<xyz>1 0 0</xyz>
				<dynamics>
					<friction>0.01</friction>
					<damping>0.1</damping>
				</dynamics>
			</axis2>
		</joint>
		<joint type="universal" name="lowerArm4ToUpperArm4"> 
			<parent>upperArm4</parent>
			<child>lowerArm4</child>
			<axis>
				<xyz>0 1 0</xyz>
				<dynamics>
					<friction>0.01</friction>
					<damping>0.1</damping>
				</dynamics>
			</axis>
			<axis2>
				<xyz>1 0 0</xyz>
				<dynamics>
					<friction>0.01</friction>
					<damping>0.1</damping>
				</dynamics>
			</axis2>
		</joint>
		<joint type="universal" name="lowerArm5ToUpperArm5"> 
			<parent>upperArm5</parent>
			<child>lowerArm5</child>
			<axis>
				<xyz>0 1 0</xyz>
				<dynamics>
					<friction>0.01</friction>
					<damping>0.1</damping>
				</dynamics>
			</axis>
			<axis2>
				<xyz>1 0 0</xyz>
				<dynamics>
					<friction>0.01</friction>
					<damping>0.1</damping>
				</dynamics>
			</axis2>
		</joint>
		<joint type="universal" name="lowerArm6ToUpperArm6"> 
			<parent>upperArm6</parent>
			<child>lowerArm6</child>
			<axis>
				<xyz>0 1 0</xyz>
				<dynamics>
					<friction>0.01</friction>
					<damping>0.1</damping>
				</dynamics>
			</axis>
			<axis2>
				<xyz>1 0 0</xyz>
				<dynamics>
					<friction>0.01</friction>
					<damping>0.1</damping>
				</dynamics>
			</axis2>
		</joint>
		<!-- Effector -->
		<joint type="universal" name="lowerArm1ToEffector"> 
			<parent>effector</parent>
			<child>lowerArm1</child>
			<pose>0 0 -0.300 0 0 0</pose>
			<axis>
				<xyz>0 1 0</xyz>
				<dynamics>
					<friction>0.01</friction>
					<damping>0.1</damping>
				</dynamics>
			</axis>
			<axis2>
				<xyz>1 0 0</xyz>
				<dynamics>
					<friction>0.01</friction>
					<damping>0.1</damping>
				</dynamics>
			</axis2>
		</joint>
		<joint type="universal" name="lowerArm2ToEffector"> 
			<parent>effector</parent>
			<child>lowerArm2</child>
			<pose>0 0 -0.300 0 0 0</pose>
			<axis>
				<xyz>0 1 0</xyz>
				<dynamics>
					<friction>0.01</friction>
					<damping>0.1</damping>
				</dynamics>
			</axis>
			<axis2>
				<xyz>1 0 0</xyz>
				<dynamics>
					<friction>0.01</friction>
					<damping>0.1</damping>
				</dynamics>
			</axis2>
		</joint>
		<joint type="universal" name="lowerArm3ToEffector"> 
			<parent>effector</parent>
			<child>lowerArm3</child>
			<pose>0 0 -0.300 0 0 0</pose>
			<axis>
				<xyz>0 1 0</xyz>
				<dynamics>
					<friction>0.01</friction>
					<damping>0.1</damping>
				</dynamics>
			</axis>
			<axis2>
				<xyz>1 0 0</xyz>
				<dynamics>
					<friction>0.01</friction>
					<damping>0.1</damping>
				</dynamics>
			</axis2>
		</joint>
		<joint type="universal" name="lowerArm4ToEffector"> 
			<parent>effector</parent>
			<child>lowerArm4</child>
			<pose>0 0 -0.300 0 0 0</pose>
			<axis>
				<xyz>0 1 0</xyz>
				<dynamics>
					<friction>0.01</friction>
					<damping>0.1</damping>
				</dynamics>
			</axis>
			<axis2>
				<xyz>1 0 0</xyz>
				<dynamics>
					<friction>0.01</friction>
					<damping>0.1</damping>
				</dynamics>
			</axis2>
		</joint>
		<joint type="universal" name="lowerArm5ToEffector"> 
			<parent>effector</parent>
			<child>lowerArm5</child>
			<pose>0 0 -0.300 0 0 0</pose>
			<axis>
				<xyz>0 1 0</xyz>
				<dynamics>
					<friction>0.01</friction>
					<damping>0.1</damping>
				</dynamics>
			</axis>
			<axis2>
				<xyz>1 0 0</xyz>
				<dynamics>
					<friction>0.01</friction>
					<damping>0.1</damping>
				</dynamics>
			</axis2>
		</joint>
		<joint type="universal" name="lowerArm6ToEffector"> 
			<parent>effector</parent>
			<child>lowerArm6</child>
			<pose>0 0 -0.300 0 0 0</pose>
			<axis>
				<xyz>0 1 0</xyz>
				<dynamics>
					<friction>0.01</friction>
					<damping>0.1</damping>
				</dynamics>
			</axis>
			<axis2>
				<xyz>1 0 0</xyz>
				<dynamics>
					<friction>0.01</friction>
					<damping>0.1</damping>
				</dynamics>
			</axis2>
		</joint>
	</model>
</sdf>
